<?xml version="1.0" ?>
<!-- =================================================================================== -->
<!-- |    This document was autogenerated by xacro from simple_fwb.xacro               | -->
<!-- |    EDITING THIS FILE BY HAND IS NOT RECOMMENDED                                 | -->
<!-- =================================================================================== -->
<!-- A four wheel robot -->
<robot name="fw_robot">
  <!-- Wheel height -->
  <!-- Dummy link for the world -->
  <link name="world">
    </link>
  <!-- Main body link -->
  <link name="body">
    <inertial>
      <origin rpy="0.0 0.0 0.0" xyz="0.0 0.0 0.0"/>
      <mass value="2.0"/>
      <inertia ixx="0.05208333333333333" ixy="0.0" ixz="0.0" iyy="0.17708333333333331" iyz="0.0" izz="0.20833333333333331"/>
    </inertial>
    <visual>
      <origin rpy="0.0 0.0 0.0" xyz="0.0 0.0 0.0"/>
      <geometry>
        <box size="1 0.5 0.25"/>
      </geometry>
    </visual>
  </link>
  <!-- Joint for the main body link -->
  <joint name="body_world_fixed" type="fixed">
    <origin rpy="0.0 0.0 0.0" xyz="0.0 0.0 0.25"/>
    <parent link="world"/>
    <child link="body"/>
  </joint>
  <!-- Link -->
  <link name="fl_wheel">
    <inertial>
      <origin rpy="0.0 0.0 0.0" xyz="0.0 0.0 0.0"/>
      <mass value="0.25"/>
      <inertia ixx="0.0010579427083333333" ixy="0.0" ixz="0.0" iyy="0.0010579427083333333" iyz="0.0" izz="0.001953125"/>
    </inertial>
    <visual>
      <origin rpy="0.0 0.0 0.0" xyz="0.0 0.0 0.0"/>
      <geometry>
        <cylinder length="0.0625" radius="0.125"/>
      </geometry>
    </visual>
  </link>
  <!-- Joint from wheel to body -->
  <joint name="fl_wheel_joint" type="continuous">
    <origin rpy="-1.5707963267948966 0.0 0.0" xyz="0.5 0.28125 -0.125"/>
    <parent link="body"/>
    <child link="fl_wheel"/>
    <axis xyz="0.0 0.0 1.0"/>
  </joint>
  <!-- Link -->
  <link name="fr_wheel">
    <inertial>
      <origin rpy="0.0 0.0 0.0" xyz="0.0 0.0 0.0"/>
      <mass value="0.25"/>
      <inertia ixx="0.0010579427083333333" ixy="0.0" ixz="0.0" iyy="0.0010579427083333333" iyz="0.0" izz="0.001953125"/>
    </inertial>
    <visual>
      <origin rpy="0.0 0.0 0.0" xyz="0.0 0.0 0.0"/>
      <geometry>
        <cylinder length="0.0625" radius="0.125"/>
      </geometry>
    </visual>
  </link>
  <!-- Joint from wheel to body -->
  <joint name="fr_wheel_joint" type="continuous">
    <origin rpy="-1.5707963267948966 0.0 0.0" xyz="0.5 -0.28125 -0.125"/>
    <parent link="body"/>
    <child link="fr_wheel"/>
    <axis xyz="0.0 0.0 1.0"/>
  </joint>
  <!-- Link -->
  <link name="hl_wheel">
    <inertial>
      <origin rpy="0.0 0.0 0.0" xyz="0.0 0.0 0.0"/>
      <mass value="0.25"/>
      <inertia ixx="0.0010579427083333333" ixy="0.0" ixz="0.0" iyy="0.0010579427083333333" iyz="0.0" izz="0.001953125"/>
    </inertial>
    <visual>
      <origin rpy="0.0 0.0 0.0" xyz="0.0 0.0 0.0"/>
      <geometry>
        <cylinder length="0.0625" radius="0.125"/>
      </geometry>
    </visual>
  </link>
  <!-- Joint from wheel to body -->
  <joint name="hl_wheel_joint" type="continuous">
    <origin rpy="-1.5707963267948966 0.0 0.0" xyz="-0.5 0.28125 -0.125"/>
    <parent link="body"/>
    <child link="hl_wheel"/>
    <axis xyz="0.0 0.0 1.0"/>
  </joint>
  <!-- Link -->
  <link name="hr_wheel">
    <inertial>
      <origin rpy="0.0 0.0 0.0" xyz="0.0 0.0 0.0"/>
      <mass value="0.25"/>
      <inertia ixx="0.0010579427083333333" ixy="0.0" ixz="0.0" iyy="0.0010579427083333333" iyz="0.0" izz="0.001953125"/>
    </inertial>
    <visual>
      <origin rpy="0.0 0.0 0.0" xyz="0.0 0.0 0.0"/>
      <geometry>
        <cylinder length="0.0625" radius="0.125"/>
      </geometry>
    </visual>
  </link>
  <!-- Joint from wheel to body -->
  <joint name="hr_wheel_joint" type="continuous">
    <origin rpy="-1.5707963267948966 0.0 0.0" xyz="-0.5 0.28125 -0.125"/>
    <parent link="body"/>
    <child link="hr_wheel"/>
    <axis xyz="0.0 0.0 1.0"/>
  </joint>
  <!-- Front Left -->
</robot>

