<?xml version="1.0" ?>
<!-- =================================================================================== -->
<!-- |    This document was autogenerated by xacro from simple_fwb.xacro               | -->
<!-- |    EDITING THIS FILE BY HAND IS NOT RECOMMENDED                                 | -->
<!-- =================================================================================== -->
<!-- A four wheel robot -->
<!-- 
    XACRO (XML Macro) is a powerful way of writing robot description files. These files can be later build as URDF
    files. They allow modularization (where you can include other XACRO files for the same robot, distributing a lot
    of load) and provide methods of creating and calling functions.

    Snippet reference page: https://wiki.ros.org/xacro

    Remember to include the xmlns for XACRO (so that the tags can be recognized).
-->
<robot name="fw_robot">
  <!-- Wheel height (m) -->
  <!-- Dummy link for the world -->
  <link name="world">
    </link>
  <!-- Main body link -->
  <link name="body">
    <inertial>
      <origin rpy="0.0 0.0 0.0" xyz="0.0 0.0 0.0"/>
      <mass value="20"/>
      <inertia ixx="0.4066666666666666" ixy="0.0" ixz="0.0" iyy="0.6058933333333333" iyz="0.0" izz="0.7872266666666665"/>
    </inertial>
    <visual>
      <origin rpy="0.0 0.0 0.0" xyz="0.0 0.0 0.0"/>
      <geometry>
        <box size="0.544 0.42 0.26"/>
      </geometry>
    </visual>
  </link>
  <!-- Joint for the main body link -->
  <joint name="body_world_fixed" type="fixed">
    <origin rpy="0.0 0.0 0.0" xyz="0.0 0.0 0.29500000000000004"/>
    <parent link="world"/>
    <child link="body"/>
  </joint>
  <!-- Link -->
  <link name="fl_wheel">
    <inertial>
      <origin rpy="0.0 0.0 0.0" xyz="0.0 0.0 0.0"/>
      <mass value="1"/>
      <inertia ixx="0.008108333333333334" ixy="0.0" ixz="0.0" iyy="0.008108333333333334" iyz="0.0" izz="0.013612500000000001"/>
    </inertial>
    <visual>
      <origin rpy="0.0 0.0 0.0" xyz="0.0 0.0 0.0"/>
      <geometry>
        <cylinder length="0.125" radius="0.165"/>
      </geometry>
    </visual>
  </link>
  <!-- Joint from wheel to body -->
  <joint name="fl_wheel_joint" type="continuous">
    <origin rpy="-1.5707963267948966 0.0 0.0" xyz="0.272 0.27249999999999996 -0.13"/>
    <parent link="body"/>
    <child link="fl_wheel"/>
    <axis xyz="0.0 0.0 1.0"/>
  </joint>
  <!-- Link -->
  <link name="fr_wheel">
    <inertial>
      <origin rpy="0.0 0.0 0.0" xyz="0.0 0.0 0.0"/>
      <mass value="1"/>
      <inertia ixx="0.008108333333333334" ixy="0.0" ixz="0.0" iyy="0.008108333333333334" iyz="0.0" izz="0.013612500000000001"/>
    </inertial>
    <visual>
      <origin rpy="0.0 0.0 0.0" xyz="0.0 0.0 0.0"/>
      <geometry>
        <cylinder length="0.125" radius="0.165"/>
      </geometry>
    </visual>
  </link>
  <!-- Joint from wheel to body -->
  <joint name="fr_wheel_joint" type="continuous">
    <origin rpy="-1.5707963267948966 0.0 0.0" xyz="0.272 -0.27249999999999996 -0.13"/>
    <parent link="body"/>
    <child link="fr_wheel"/>
    <axis xyz="0.0 0.0 1.0"/>
  </joint>
  <!-- Link -->
  <link name="hl_wheel">
    <inertial>
      <origin rpy="0.0 0.0 0.0" xyz="0.0 0.0 0.0"/>
      <mass value="1"/>
      <inertia ixx="0.008108333333333334" ixy="0.0" ixz="0.0" iyy="0.008108333333333334" iyz="0.0" izz="0.013612500000000001"/>
    </inertial>
    <visual>
      <origin rpy="0.0 0.0 0.0" xyz="0.0 0.0 0.0"/>
      <geometry>
        <cylinder length="0.125" radius="0.165"/>
      </geometry>
    </visual>
  </link>
  <!-- Joint from wheel to body -->
  <joint name="hl_wheel_joint" type="continuous">
    <origin rpy="-1.5707963267948966 0.0 0.0" xyz="-0.272 0.27249999999999996 -0.13"/>
    <parent link="body"/>
    <child link="hl_wheel"/>
    <axis xyz="0.0 0.0 1.0"/>
  </joint>
  <!-- Link -->
  <link name="hr_wheel">
    <inertial>
      <origin rpy="0.0 0.0 0.0" xyz="0.0 0.0 0.0"/>
      <mass value="1"/>
      <inertia ixx="0.008108333333333334" ixy="0.0" ixz="0.0" iyy="0.008108333333333334" iyz="0.0" izz="0.013612500000000001"/>
    </inertial>
    <visual>
      <origin rpy="0.0 0.0 0.0" xyz="0.0 0.0 0.0"/>
      <geometry>
        <cylinder length="0.125" radius="0.165"/>
      </geometry>
    </visual>
  </link>
  <!-- Joint from wheel to body -->
  <joint name="hr_wheel_joint" type="continuous">
    <origin rpy="-1.5707963267948966 0.0 0.0" xyz="-0.272 -0.27249999999999996 -0.13"/>
    <parent link="body"/>
    <child link="hr_wheel"/>
    <axis xyz="0.0 0.0 1.0"/>
  </joint>
  <!-- Hind Right -->
</robot>

