<?xml version="1.0" ?>
<!-- =================================================================================== -->
<!-- |    This document was autogenerated by xacro from slbot_t5.xacro                 | -->
<!-- |    EDITING THIS FILE BY HAND IS NOT RECOMMENDED                                 | -->
<!-- =================================================================================== -->
<!-- A single joint (one movable link) robot -->
<robot name="sl_robot">
  <!-- Material properties -->
  <gazebo reference="base">
    <material>Gazebo/Orange</material>
  </gazebo>
  <gazebo reference="link1">
    <material>Gazebo/Red</material>
  </gazebo>
  <!-- Dummy link -->
  <link name="world">
    </link>
  <!-- Main <link> element -->
  <link name="base">
    <!-- Visual: appearance -->
    <visual>
      <!-- Origin of the visual mesh -->
      <origin rpy="0.0 0.0 0.0" xyz="-0.06 -0.225 0.0"/>
      <geometry>
        <!-- Mesh file -->
        <mesh filename="package://basic_robotics/urdf/meshes/Base_t5.STL" scale="0.001 0.001 0.001"/>
      </geometry>
    </visual>
    <!-- Collision: physics -->
    <collision>
      <!-- Origin of the visual mesh -->
      <origin rpy="0.0 0.0 0.0" xyz="-0.06 -0.225 0.0"/>
      <geometry>
        <!-- Mesh file -->
        <mesh filename="package://basic_robotics/urdf/meshes/Base_t5.STL" scale="0.001 0.001 0.001"/>
      </geometry>
    </collision>
    <!-- Inertia: 3D moment of inertia -->
    <inertial>
      <origin rpy="0.0 0.0 0.0" xyz="0.0 0.0 0.0"/>
      <mass value="82.74614"/>
      <!-- Inertial tensor -->
      <inertia ixx="2.746313" ixy="0.0" ixz="0.0" iyy="1.721184" iyz="0.0" izz="1.254731"/>
    </inertial>
  </link>
  <!-- Main <link> element -->
  <link name="link1">
    <!-- Visual: appearance -->
    <visual>
      <!-- Origin of the visual mesh -->
      <origin rpy="0.0 0.0 0.0" xyz="-0.03 -0.06 -0.06"/>
      <geometry>
        <!-- Mesh file -->
        <mesh filename="package://basic_robotics/urdf/meshes/Link_t5.STL" scale="0.001 0.001 0.001"/>
      </geometry>
    </visual>
    <!-- Collision: physics -->
    <collision>
      <!-- Origin of the visual mesh -->
      <origin rpy="0.0 0.0 0.0" xyz="-0.03 -0.06 -0.06"/>
      <geometry>
        <!-- Mesh file -->
        <mesh filename="package://basic_robotics/urdf/meshes/Link_t5.STL" scale="0.001 0.001 0.001"/>
      </geometry>
    </collision>
    <!-- Inertia: 3D moment of inertia -->
    <inertial>
      <origin rpy="0.0 0.0 0.0" xyz="0.0 0.0 0.0"/>
      <mass value="7.61817"/>
      <!-- Inertial tensor -->
      <inertia ixx="0.292031" ixy="0.0" ixz="0.0" iyy="0.285400" iyz="0.0" izz="0.011201"/>
    </inertial>
  </link>
  <!-- Joint for the dummy link -->
  <joint name="dummy" type="fixed">
    <parent link="world"/>
    <child link="base"/>
  </joint>
  <!-- Joint to connect them -->
  <joint name="joint1" type="revolute">
    <parent link="base"/>
    <child link="link1"/>
    <origin rpy="0.0 0.0 0.0" xyz="0.0 0.0 0.25"/>
    <axis xyz="1.0 0.0 0.0"/>
    <limit effort="10" lower="-1.570796" upper="1.570796" velocity="10"/>
  </joint>
</robot>

